Workbook

Sheet podatki
A1: Country name | B1: Regional indicator | C1: Ladder score | D1: Standard error of ladder score | E1: upperwhisker | F1: lowerwhisker | G1: Logged GDP per capita | H1: Social support | I1: Healthy life expectancy | J1: Freedom to make life choices | K1: Generosity | L1: Perceptions of corruption | M1: Ladder score in Dystopia | N1: Explained by: Log GDP per capita | O1: Explained by: Social support | P1: Explained by: Healthy life expectancy | Q1: Explained by: Freedom to make life choices | R1: Explained by: Generosity | S1: Explained by: Perceptions of corruption | T1: Dystopia + residual
A2: Finland | B2: Western Europe | C2: =7842/(1000) -> 7.842 | D2: 0.032 | E2: 7904 | F2: 7780 | G2: =10775/(1000) -> 10.775 | H2: 0.954 | I2: =72000/(1000) -> 72 | J2: 0.949 | K2: -0.098 | L2: 0.186 | M2: 2430 | N2: 1446 | O2: 1106 | P2: 0.741 | Q2: 0.691 | R2: 0.124 | S2: 0.481 | T2: 3253
A3: Denmark | B3: Western Europe | C3: =7620/(1000) -> 7.62 | D3: 0.035 | E3: 7687 | F3: 7552 | G3: =10933/(1000) -> 10.933 | H3: 0.954 | I3: =72700/(1000) -> 72.7 | J3: 0.946 | K3: 0.03 | L3: 0.179 | M3: 2430 | N3: 1502 | O3: 1108 | P3: 0.763 | Q3: 0.686 | R3: 0.208 | S3: 0.485 | T3: 2868
A4: Switzerland | B4: Western Europe | C4: =7571/(1000) -> 7.571 | D4: 0.036 | E4: 7643 | F4: 7500 | G4: =11117/(1000) -> 11.117 | H4: 0.942 | I4: =74400/(1000) -> 74.4 | J4: 0.919 | K4: 0.025 | L4: 0.292 | M4: 2430 | N4: 1566 | O4: 1079 | P4: 0.816 | Q4: 0.653 | R4: 0.204 | S4: 0.413 | T4: 2839
A5: Iceland | B5: Western Europe | C5: =7554/(1000) -> 7.554 | D5: 0.059 | E5: 7670 | F5: 7438 | G5: =10878/(1000) -> 10.878 | H5: 0.983 | I5: =73000/(1000) -> 73 | J5: 0.955 | K5: 0.16 | L5: 0.673 | M5: 2430 | N5: 1482 | O5: 1172 | P5: 0.772 | Q5: 0.698 | R5: 0.293 | S5: 0.17 | T5: 2967
A6: Netherlands | B6: Western Europe | C6: =7464/(1000) -> 7.464 | D6: 0.027 | E6: 7518 | F6: 7410 | G6: =10932/(1000) -> 10.932 | H6: 0.942 | I6: =72400/(1000) -> 72.4 | J6: 0.913 | K6: 0.175 | L6: 0.338 | M6: 2430 | N6: 1501 | O6: 1079 | P6: 0.753 | Q6: 0.647 | R6: 0.302 | S6: 0.384 | T6: 2798
A7: Norway | B7: Western Europe | C7: =7392/(1000) -> 7.392 | D7: 0.035 | E7: 7462 | F7: 7323 | G7: =11053/(1000) -> 11.053 | H7: 0.954 | I7: =73300/(1000) -> 73.3 | J7: 0.96 | K7: 0.093 | L7: 0.27 | M7: 2430 | N7: 1543 | O7: 1108 | P7: 0.782 | Q7: 0.703 | R7: 0.249 | S7: 0.427 | T7: 2580
A8: Sweden | B8: Western Europe | C8: =7363/(1000) -> 7.363 | D8: 0.036 | E8: 7433 | F8: 7293 | G8: =10867/(1000) -> 10.867 | H8: 0.934 | I8: =72700/(1000) -> 72.7 | J8: 0.945 | K8: 0.086 | L8: 0.237 | M8: 2430 | N8: 1478 | O8: 1062 | P8: 0.763 | Q8: 0.685 | R8: 0.244 | S8: 0.448 | T8: 2683
A9: Luxembourg | B9: Western Europe | C9: =7324/(1000) -> 7.324 | D9: 0.037 | E9: 7396 | F9: 7252 | G9: =11647/(1000) -> 11.647 | H9: 0.908 | I9: =72600/(1000) -> 72.6 | J9: 0.907 | K9: -0.034 | L9: 0.386 | M9: 2430 | N9: 1751 | O9: 1003 | P9: 0.76 | Q9: 0.639 | R9: 0.166 | S9: 0.353 | T9: 2653
A10: New Zealand | B10: North America and ANZ | C10: =7277/(1000) -> 7.277 | D10: 0.04 | E10: 7355 | F10: 7198 | G10: =10643/(1000) -> 10.643 | H10: 0.948 | I10: =73400/(1000) -> 73.4 | J10: 0.929 | K10: 0.134 | L10: 0.242 | M10: 2430 | N10: 1400 | O10: 1094 | P10: 0.785 | Q10: 0.665 | R10: 0.276 | S10: 0.445 | T10: 2612
A11: Austria | B11: Western Europe | C11: =7268/(1000) -> 7.268 | D11: 0.036 | E11: 7337 | F11: 7198 | G11: =10906/(1000) -> 10.906 | H11: 0.934 | I11: =73300/(1000) -> 73.3 | J11: 0.908 | K11: 0.042 | L11: 0.481 | M11: 2430 | N11: 1492 | O11: 1062 | P11: 0.782 | Q11: 0.64 | R11: 0.215 | S11: 0.292 | T11: 2784
A12: Australia | B12: North America and ANZ | C12: =7183/(1000) -> 7.183 | D12: 0.041 | E12: 7265 | F12: 7102 | G12: =10796/(1000) -> 10.796 | H12: 0.94 | I12: =73900/(1000) -> 73.9 | J12: 0.914 | K12: 0.159 | L12: 0.442 | M12: 2430 | N12: 1453 | O12: 1076 | P12: 0.801 | Q12: 0.647 | R12: 0.291 | S12: 0.317 | T12: 2598
A13: Israel | B13: Middle East and North Africa | C13: =7157/(1000) -> 7.157 | D13: 0.034 | E13: 7224 | F13: 7090 | G13: =10575/(1000) -> 10.575 | H13: 0.939 | I13: =73503/(1000) -> 73.503 | J13: 0.8 | K13: 0.031 | L13: 0.753 | M13: 2430 | N13: 1376 | O13: 1074 | P13: 0.788 | Q13: 0.509 | R13: 0.208 | S13: 0.119 | T13: 3083
A14: Germany | B14: Western Europe | C14: =7155/(1000) -> 7.155 | D14: 0.04 | E14: 7232 | F14: 7077 | G14: =10873/(1000) -> 10.873 | H14: 0.903 | I14: =72500/(1000) -> 72.5 | J14: 0.875 | K14: 0.011 | L14: 0.46 | M14: 2430 | N14: 1480 | O14: 0.993 | P14: 0.757 | Q14: 0.6 | R14: 0.195 | S14: 0.306 | T14: 2824
A15: Canada | B15: North America and ANZ | C15: =7103/(1000) -> 7.103 | D15: 0.042 | E15: 7185 | F15: 7021 | G15: =10776/(1000) -> 10.776 | H15: 0.926 | I15: =73800/(1000) -> 73.8 | J15: 0.915 | K15: 0.089 | L15: 0.415 | M15: 2430 | N15: 1447 | O15: 1044 | P15: 0.798 | Q15: 0.648 | R15: 0.246 | S15: 0.335 | T15: 2585
A16: Ireland | B16: Western Europe | C16: =7085/(1000) -> 7.085 | D16: 0.04 | E16: 7164 | F16: 7006 | G16: =11342/(1000) -> 11.342 | H16: 0.947 | I16: =72400/(1000) -> 72.4 | J16: 0.879 | K16: 0.077 | L16: 0.363 | M16: 2430 | N16: 1644 | O16: 1092 | P16: 0.753 | Q16: 0.606 | R16: 0.238 | S16: 0.367 | T16: 2384
A17: Costa Rica | B17: Latin America and Caribbean | C17: =7069/(1000) -> 7.069 | D17: 0.056 | E17: 7179 | F17: 6960 | G17: =9880/(1000) -> 9.88 | H17: 0.891 | I17: =71400/(1000) -> 71.4 | J17: 0.934 | K17: -0.126 | L17: 0.809 | M17: 2430 | N17: 1134 | O17: 0.966 | P17: 0.722 | Q17: 0.673 | R17: 0.105 | S17: 0.083 | T17: 3387
A18: United Kingdom | B18: Western Europe | C18: =7064/(1000) -> 7.064 | D18: 0.038 | E18: 7138 | F18: 6990 | G18: =10707/(1000) -> 10.707 | H18: 0.934 | I18: =72500/(1000) -> 72.5 | J18: 0.859 | K18: 0.233 | L18: 0.459 | M18: 2430 | N18: 1423 | O18: 1062 | P18: 0.757 | Q18: 0.58 | R18: 0.34 | S18: 0.306 | T18: 2596
A19: Czech Republic | B19: Central and Eastern Europe | C19: =6965/(1000) -> 6.965 | D19: 0.049 | E19: 7062 | F19: 6868 | G19: =10556/(1000) -> 10.556 | H19: 0.947 | I19: =70807/(1000) -> 70.807 | J19: 0.858 | K19: -0.208 | L19: 0.868 | M19: 2430 | N19: 1370 | O19: 1090 | P19: 0.703 | Q19: 0.58 | R19: 0.052 | S19: 0.046 | T19: 3124
A20: United States | B20: North America and ANZ | C20: =6951/(1000) -> 6.951 | D20: 0.049 | E20: 7047 | F20: 6856 | G20: =11023/(1000) -> 11.023 | H20: 0.92 | I20: =68200/(1000) -> 68.2 | J20: 0.837 | K20: 0.098 | L20: 0.698 | M20: 2430 | N20: 1533 | O20: 1030 | P20: 0.621 | Q20: 0.554 | R20: 0.252 | S20: 0.154 | T20: 2807
A21: Belgium | B21: Western Europe | C21: =6834/(1000) -> 6.834 | D21: 0.034 | E21: 6901 | F21: 6767 | G21: =10823/(1000) -> 10.823 | H21: 0.906 | I21: =72199/(1000) -> 72.199 | J21: 0.783 | K21: -0.153 | L21: 0.646 | M21: 2430 | N21: 1463 | O21: 0.998 | P21: 0.747 | Q21: 0.489 | R21: 0.088 | S21: 0.187 | T21: 2862
A22: France | B22: Western Europe | C22: =6690/(1000) -> 6.69 | D22: 0.037 | E22: 6762 | F22: 6618 | G22: =10704/(1000) -> 10.704 | H22: 0.942 | I22: =74000/(1000) -> 74 | J22: 0.822 | K22: -0.147 | L22: 0.571 | M22: 2430 | N22: 1421 | O22: 1081 | P22: 0.804 | Q22: 0.536 | R22: 0.092 | S22: 0.235 | T22: 2521
A23: Bahrain | B23: Middle East and North Africa | C23: =6647/(1000) -> 6.647 | D23: 0.068 | E23: 6779 | F23: 6514 | G23: =10669/(1000) -> 10.669 | H23: 0.862 | I23: =69495/(1000) -> 69.495 | J23: 0.925 | K23: 0.089 | L23: 0.722 | M23: 2430 | N23: 1409 | O23: 0.899 | P23: 0.662 | Q23: 0.661 | R23: 0.246 | S23: 0.139 | T23: 2631
A24: Malta | B24: Western Europe | C24: =6602/(1000) -> 6.602 | D24: 0.044 | E24: 6688 | F24: 6516 | G24: =10674/(1000) -> 10.674 | H24: 0.931 | I24: =72200/(1000) -> 72.2 | J24: 0.927 | K24: 0.133 | L24: 0.653 | M24: 2430 | N24: 1411 | O24: 1055 | P24: 0.747 | Q24: 0.664 | R24: 0.275 | S24: 0.183 | T24: 2268
A25: Taiwan Province of China | B25: East Asia | C25: =6584/(1000) -> 6.584 | D25: 0.038 | E25: 6659 | F25: 6510 | G25: =10871/(1000) -> 10.871 | H25: 0.898 | I25: =69600/(1000) -> 69.6 | J25: 0.784 | K25: -0.07 | L25: 0.721 | M25: 2430 | N25: 1480 | O25: 0.982 | P25: 0.665 | Q25: 0.49 | R25: 0.142 | S25: 0.139 | T25: 2687
A26: United Arab Emirates | B26: Middle East and North Africa | C26: =6561/(1000) -> 6.561 | D26: 0.039 | E26: 6637 | F26: 6484 | G26: =11085/(1000) -> 11.085 | H26: 0.844 | I26: =67333/(1000) -> 67.333 | J26: 0.932 | K26: 0.074 | L26: 0.589 | M26: 2430 | N26: 1555 | O26: 0.86 | P26: 0.594 | Q26: 0.67 | R26: 0.236 | S26: 0.223 | T26: 2422
A27: Saudi Arabia | B27: Middle East and North Africa | C27: =6494/(1000) -> 6.494 | D27: 0.056 | E27: 6604 | F27: 6384 | G27: =10743/(1000) -> 10.743 | H27: 0.891 | I27: =66603/(1000) -> 66.603 | J27: 0.877 | K27: -0.149 | L27: 0.684 | M27: 2430 | N27: 1435 | O27: 0.964 | P27: 0.571 | Q27: 0.603 | R27: 0.09 | S27: 0.163 | T27: 2668
A28: Spain | B28: Western Europe | C28: =6491/(1000) -> 6.491 | D28: 0.042 | E28: 6574 | F28: 6408 | G28: =10571/(1000) -> 10.571 | H28: 0.932 | I28: =74700/(1000) -> 74.7 | J28: 0.761 | K28: -0.081 | L28: 0.745 | M28: 2430 | N28: 1375 | O28: 1057 | P28: 0.826 | Q28: 0.462 | R28: 0.135 | S28: 0.124 | T28: 2513
A29: Italy | B29: Western Europe | C29: =6483/(1000) -> 6.483 | D29: 0.045 | E29: 6572 | F29: 6395 | G29: =10623/(1000) -> 10.623 | H29: 0.88 | I29: =73800/(1000) -> 73.8 | J29: 0.693 | K29: -0.084 | L29: 0.866 | M29: 2430 | N29: 1393 | O29: 0.94 | P29: 0.798 | Q29: 0.379 | R29: 0.133 | S29: 0.047 | T29: 2794
A30: Slovenia | B30: Central and Eastern Europe | C30: =6461/(1000) -> 6.461 | D30: 0.043 | E30: 6546 | F30: 6376 | G30: =10529/(1000) -> 10.529 | H30: 0.948 | I30: =71400/(1000) -> 71.4 | J30: 0.949 | K30: -0.101 | L30: 0.806 | M30: 2430 | N30: 1360 | O30: 1093 | P30: 0.722 | Q30: 0.69 | R30: 0.122 | S30: 0.085 | T30: 2388
A31: Guatemala | B31: Latin America and Caribbean | C31: =6435/(1000) -> 6.435 | D31: 0.073 | E31: 6577 | F31: 6292 | G31: =9053/(1000) -> 9.053 | H31: 0.813 | I31: =64958/(1000) -> 64.958 | J31: 0.906 | K31: -0.038 | L31: 0.775 | M31: 2430 | N31: 0.845 | O31: 0.79 | P31: 0.519 | Q31: 0.638 | R31: 0.163 | S31: 0.105 | T31: 3375
A32: Uruguay | B32: Latin America and Caribbean | C32: =6431/(1000) -> 6.431 | D32: 0.046 | E32: 6521 | F32: 6341 | G32: =9966/(1000) -> 9.966 | H32: 0.925 | I32: =69100/(1000) -> 69.1 | J32: 0.896 | K32: -0.092 | L32: 0.59 | M32: 2430 | N32: 1164 | O32: 1042 | P32: 0.649 | Q32: 0.625 | R32: 0.128 | S32: 0.223 | T32: 2600
A33: Singapore | B33: Southeast Asia | C33: =6377/(1000) -> 6.377 | D33: 0.043 | E33: 6460 | F33: 6293 | G33: =11488/(1000) -> 11.488 | H33: 0.915 | I33: =76953/(1000) -> 76.953 | J33: 0.927 | K33: -0.018 | L33: 0.082 | M33: 2430 | N33: 1695 | O33: 1019 | P33: 0.897 | Q33: 0.664 | R33: 0.176 | S33: 0.547 | T33: 1379
A34: Kosovo | B34: Central and Eastern Europe | C34: =6372/(1000) -> 6.372 | D34: 0.059 | E34: 6487 | F34: 6257 | G34: =9318/(1000) -> 9.318 | H34: 0.821 | I34: =63813/(1000) -> 63.813 | J34: 0.869 | K34: 0.257 | L34: 0.917 | M34: 2430 | N34: 0.937 | O34: 0.807 | P34: 0.483 | Q34: 0.593 | R34: 0.356 | S34: 0.014 | T34: 3182
A35: Slovakia | B35: Central and Eastern Europe | C35: =6331/(1000) -> 6.331 | D35: 0.041 | E35: 6411 | F35: 6251 | G35: =10369/(1000) -> 10.369 | H35: 0.936 | I35: =69201/(1000) -> 69.201 | J35: 0.766 | K35: -0.124 | L35: 0.911 | M35: 2430 | N35: 1304 | O35: 1066 | P35: 0.653 | Q35: 0.468 | R35: 0.107 | S35: 0.018 | T35: 2714
A36: Brazil | B36: Latin America and Caribbean | C36: =6330/(1000) -> 6.33 | D36: 0.043 | E36: 6415 | F36: 6245 | G36: =9577/(1000) -> 9.577 | H36: 0.882 | I36: =66601/(1000) -> 66.601 | J36: 0.804 | K36: -0.071 | L36: 0.756 | M36: 2430 | N36: 1028 | O36: 0.944 | P36: 0.571 | Q36: 0.514 | R36: 0.142 | S36: 0.117 | T36: 3015
A37: Mexico | B37: Latin America and Caribbean | C37: =6317/(1000) -> 6.317 | D37: 0.053 | E37: 6420 | F37: 6213 | G37: =9859/(1000) -> 9.859 | H37: 0.831 | I37: =68597/(1000) -> 68.597 | J37: 0.862 | K37: -0.147 | L37: 0.799 | M37: 2430 | N37: 1126 | O37: 0.83 | P37: 0.634 | Q37: 0.585 | R37: 0.092 | S37: 0.089 | T37: 2961
A38: Jamaica | B38: Latin America and Caribbean | C38: =6309/(1000) -> 6.309 | D38: 0.156 | E38: 6615 | F38: 6004 | G38: =9186/(1000) -> 9.186 | H38: 0.877 | I38: =67500/(1000) -> 67.5 | J38: 0.89 | K38: -0.137 | L38: 0.884 | M38: 2430 | N38: 0.891 | O38: 0.932 | P38: 0.599 | Q38: 0.618 | R38: 0.099 | S38: 0.035 | T38: 3135
A39: Lithuania | B39: Central and Eastern Europe | C39: =6255/(1000) -> 6.255 | D39: 0.045 | E39: 6344 | F39: 6167 | G39: =10499/(1000) -> 10.499 | H39: 0.935 | I39: =67906/(1000) -> 67.906 | J39: 0.773 | K39: -0.203 | L39: 0.826 | M39: 2430 | N39: 1350 | O39: 1065 | P39: 0.612 | Q39: 0.476 | R39: 0.056 | S39: 0.073 | T39: 2624
A40: Cyprus | B40: Western Europe | C40: =6223/(1000) -> 6.223 | D40: 0.049 | E40: 6319 | F40: 6128 | G40: =10576/(1000) -> 10.576 | H40: 0.802 | I40: =73898/(1000) -> 73.898 | J40: 0.763 | K40: -0.015 | L40: 0.844 | M40: 2430 | N40: 1377 | O40: 0.765 | P40: 0.801 | Q40: 0.464 | R40: 0.178 | S40: 0.061 | T40: 2578
...

Sheet analiza
A1: Row Labels | B1: Count of Regional indicator
A2: Central and Eastern Europe | B2: 17
A3: Commonwealth of Independent States | B3: 12
A4: East Asia | B4: 6
A5: Latin America and Caribbean | B5: 20
A6: Middle East and North Africa | B6: 17
A7: North America and ANZ | B7: 4
A8: South Asia | B8: 7
A9: Southeast Asia | B9: 9
A10: Sub-Saharan Africa | B10: 36
A11: Western Europe | B11: 21
A12: Grand Total | B12: 149
A14: Katera komponenta (GDP, zdravje, podpora …) ima najmočnejšo povezavo s srečo (Ladder score)?
A16: Uporaba Pearsonovega koeficienta korelacije (r), ki napove korelacijo:
A17: ,=CORREL(X;X)
A18: Povezava med ladder score (vrednost sreče) in komponento
A19: GDP | B19: =CORREL(podatki!$C$2:$C$150,podatki!$G$2:$G$150) -> 0.7897597 | C19: Močna pozitivna korelacija (najmočnejša) | D19: Vrednost r | E19: Pomen
A20: Social support | B20: =CORREL(podatki!$H$2:$H$150,podatki!$C$2:$C$150) -> 0.75688765 | C20: Močna pozitivna korelacija | D20: +1.00 | E20: Popolna pozitivna korelacija (npr. več B = več A)
A21: Healthy life expectancy | B21: =CORREL(podatki!$I$2:$I$150,podatki!$C$2:$C$150) -> 0.76809946 | C21: Močna pozitivna korelacija | D21: +0.50 do +0.99 | E21: Močna pozitivna korelacija
A22: Freedom to make life choices | B22: =CORREL(podatki!$J$2:$J$150,podatki!$C$2:$C$150) -> 0.60775307 | C22: Močna pozitivna korelacija | D22: +0.10 do +0.49 | E22: Šibka pozitivna korelacija
A23: Generosity | B23: =CORREL(podatki!$K$2:$K$150,podatki!$C$2:$C$150) -> -0.017799277 | C23: Ni korelacije | D23: 0.00 | E23: Ni korelacije
A24: Perceptions of corruption | B24: =CORREL(podatki!$L$2:$L$150,podatki!$C$2:$C$150) -> -0.42114 | C24: Šibka negativna korelacija | D24: −0.10 do −0.49 | E24: Šibka negativna korelacija
D25: −0.50 do −0.99 | E25: Močna negativna korelacija
A26: Row Labels | B26: Average of Ladder score | C26: Average of Logged GDP per capita | D26: Number of countries | E26: Popolna negativna korelacija
A27: Central and Eastern Europe | B27: 5984.7647 | C27: 10109.059 | D27: 17
A28: Commonwealth of Independent States | B28: 5467 | C28: 9401.8333 | D28: 12
A29: East Asia | B29: 5810.3333 | C29: 10367.667 | D29: 6
A30: Latin America and Caribbean | B30: 5908.05 | C30: 9370 | D30: 20
A31: Middle East and North Africa | B31: 5219.7647 | C31: 9666.1176 | D31: 17
A32: North America and ANZ | B32: 7128.5 | C32: 10809.5 | D32: 4
A33: South Asia | B33: 4441.8571 | C33: 8682.5714 | D33: 7
A34: Southeast Asia | B34: 5407.5556 | C34: 9421.4444 | D34: 9
A35: Sub-Saharan Africa | B35: 4494.4722 | C35: 8075.1944 | D35: 36
A36: Western Europe | B36: 6914.9048 | C36: 10822.714 | D36: 21
A37: Grand Total | B37: 5532.8389 | C37: 9432.2081 | D37: 149
A43: 1. Ali večja svoboda izbire življenja vedno pomeni manjšo korupcijo?
A45: Pearsonov koeficient ®:
A46: Med svobodo in korupcijo
A47: =CORREL(podatki!$J$2:$J$150,podatki!$L$2:$L$150) -> -0.40136297 | B47: Šibka negativna korelacija
B49: Number of countries | C49: Freedom to make life choices | D49: Perceptions of corruption
...

Sheet Sheet1
A1: Healthy life expectancy | B1: Generosity | J1: 1. Je bolj zdrava populacija tudi bolj velikodušna?
A2: 48478 | B2: 0.041 | J2: r
A3: 48700 | B3: -0.131 | J3: =CORREL(podatki!$I$2:$I$150,podatki!$K$2:$K$150) -> -0.16175028 | K3: šibka negativna korelacija
A4: 50102 | B4: 0.037 | J4: Po mojem mnenju korelacija ni signifikantna
A5: 50114 | B5: -0.016
A6: 50833 | B6: -0.185
A7: 51651 | B7: 0.084
A8: 51969 | B8: -0.036
A9: 52493 | B9: -0.102
A10: 53400 | B10: -0.024
A11: 53515 | B11: 0.026
A12: 53780 | B12: 0.018
A13: 54151 | B13: -0.009
A14: 54706 | B14: 0.061
A15: 54713 | B15: -0.034
A16: 54914 | B16: 0.032
... A150: 76953 | B150: -0.018

Sheet Sheet2
A1: 🔹 2. Regionalna porazdelitev
A2: ✅ Cilj: Preveri razlike med regijami
A3: 1. Ugotovi regijo z največjim povprečjem Ladder score
A4: 2. Primerjaj regije glede razkoraka med 'perceived corruption' in GDP
A5: 3. Dodaj regijsko lestvico: uredi države znotraj regij po Ladder score
A7: 1. Ugotovi regijo z največjim povprečjem Ladder score
A8: Row Labels | B8: Average of Ladder score
A9: Central and Eastern Europe | B9: 5984.7647
A10: Commonwealth of Independent States | B10: 5467
A11: East Asia | B11: 5810.3333
A12: Latin America and Caribbean | B12: 5908.05
A13: Middle East and North Africa | B13: 5219.7647
A14: North America and ANZ | B14: 7128.5 | C14: North america and anz has the highest average Ladder score
A15: South Asia | B15: 4441.8571
A16: Southeast Asia | B16: 5407.5556
A17: Sub-Saharan Africa | B17: 4494.4722
A18: Western Europe | B18: 6914.9048
A19: Grand Total | B19: 5532.8389
A21: 2. Primerjaj regije glede razkoraka med 'perceived corruption' in GDP
A22: Normalizacija perceived corruption in GDP
A24: Ko so podatki na različnoih skalah-> uporaba grafa | C24: Corruption | D24: GDP
A25: normalizacija=(vrednost-min)/razlika | B25: Min | C25: =MIN(podatki!L2:L150) -> 0.082 | D25: =MIN(podatki!G2:G150) -> 6.635
A26: Uporaba funkcije MIN in MAX | B26: Max | C26: =MAX(podatki!L2:L150) -> 0.939 | D26: =MAX(podatki!G2:G150) -> 11.647
B27: Razlika | C27: =C26-C25 -> 0.857 | D27: =D26-D25 -> 5.012
A29: Logged GDP per capita | B29: Perceptions of corruption | C29: Normalized GDP | D29: Normalized corruption | E29: Regional indicator
A30: 10775 | B30: 0.186 | C30: =(A30-$D$25)/$D$27 -> 2148.5166 | D30: =(B30-$C$25)/$C$27 -> 0.12135356 | E30: Western Europe
A31: 10933 | B31: 0.179 | C31: =(A31-$D$25)/$D$27 -> 2180.0409 | D31: =(B31-$C$25)/$C$27 -> 0.11318553 | E31: Western Europe
A32: 11117 | B32: 0.292 | C32: =(A32-$D$25)/$D$27 -> 2216.7528 | D32: =(B32-$C$25)/$C$27 -> 0.24504084 | E32: Western Europe
A33: 10878 | B33: 0.673 | C33: =(A33-$D$25)/$D$27 -> 2169.0672 | D33: =(B33-$C$25)/$C$27 -> 0.68961494 | E33: Western Europe
A34: 10932 | B34: 0.338 | C34: =(A34-$D$25)/$D$27 -> 2179.8414 | D34: =(B34-$C$25)/$C$27 -> 0.29871645 | E34: Western Europe
A35: 11053 | B35: 0.27 | C35: =(A35-$D$25)/$D$27 -> 2203.9834 | D35: =(B35-$C$25)/$C$27 -> 0.21936989 | E35: Western Europe
A36: 10867 | B36: 0.237 | C36: =(A36-$D$25)/$D$27 -> 2166.8725 | D36: =(B36-$C$25)/$C$27 -> 0.18086348 | E36: Western Europe
A37: 11647 | B37: 0.386 | C37: =(A37-$D$25)/$D$27 -> 2322.499 | D37: =(B37-$C$25)/$C$27 -> 0.35472579 | E37: Western Europe
A38: 10643 | B38: 0.242 | C38: =(A38-$D$25)/$D$27 -> 2122.1798 | D38: =(B38-$C$25)/$C$27 -> 0.18669778 | E38: North America and ANZ
A39: 10906 | B39: 0.481 | C39: =(A39-$D$25)/$D$27 -> 2174.6538 | D39: =(B39-$C$25)/$C$27 -> 0.4655776 | E39: Western Europe
A40: 10796 | B40: 0.442 | C40: =(A40-$D$25)/$D$27 -> 2152.7065 | D40: =(B40-$C$25)/$C$27 -> 0.42007001 | E40: North America and ANZ
A41: 10575 | B41: 0.753 | C41: =(A41-$D$25)/$D$27 -> 2108.6123 | D41: =(B41-$C$25)/$C$27 -> 0.78296383 | E41: Middle East and North Africa
... A64: 9577 | B64: 0.756 | C64: =(A64-$D$25)/$D$27 -> 1909.4902 | D64: =(B64-$C$25)/$C$27 -> 0.78646441 | E64: Latin America and Caribbean
A65: 9859 | B65: 0.799 | C65: =(A65-$D$25)/$D$27 -> 1965.7552 | D65: =(B65-$C$25)/$C$27 -> 0.83663944 | E65: Latin America and Caribbean | H65: 2. Primerjaj regije glede razkoraka med 'perceived corruption' in GDP
A66: 9186 | B66: 0.884 | C66: =(A66-$D$25)/$D$27 -> 1831.4775 | D66: =(B66-$C$25)/$C$27 -> 0.93582264 | E66: Latin America and Caribbean | H66: Row Labels | I66: Average of Normalized corruption | J66: Average of Normalized GDP
...

Sheet Sheet3
A1: 🔹 3. Ustvarjanje kazalnikov
A2: ✅ Cilj: Ustvari nov "index"
A3: 1. Izračunaj “Wellbeing index” kot povprečje: GDP + Social support + Freedom – Corruption
A4: 2. Uvrsti države po tem novem kazalniku in primerjaj z uradno Ladder score
A6: Country name | B6: Ladder score | C6: Wellbeing index | D6: Ranking by ladder score | E6: Ranking by wellbeing index | F6: Different ranking (ws-ls)
A7: Finland | B7: 7842 | C7: =IFERROR((AVERAGE(podatki!G2+podatki!H2+podatki!J2)-podatki!L2),"Error") -> 12.492 | D7: =RANK(Sheet3!B7,Sheet3!$B$7:$B$155) -> 1 | E7: =RANK(Sheet3!C7,Sheet3!$C$7:$C$155) -> 8 | F7: =E7-D7 -> 7
A8: Denmark | B8: 7620 | C8: =IFERROR((AVERAGE(podatki!G3+podatki!H3+podatki!J3)-podatki!L3),"Error") -> 12.654 | D8: =RANK(Sheet3!B8,Sheet3!$B$7:$B$155) -> 2 | E8: =RANK(Sheet3!C8,Sheet3!$C$7:$C$155) -> 6 | F8: =E8-D8 -> 4 | I8: Rank | J8: Wellbeing score | K8: Ladder score
A9: Switzerland | B9: 7571 | C9: =IFERROR((AVERAGE(podatki!G4+podatki!H4+podatki!J4)-podatki!L4),"Error") -> 12.686 | D9: =RANK(Sheet3!B9,Sheet3!$B$7:$B$155) -> 3 | E9: =RANK(Sheet3!C9,Sheet3!$C$7:$C$155) -> 5 | F9: =E9-D9 -> 2 | I9: 1 | J9: Singapore | K9: Finland
A10: Iceland | B10: 7554 | C10: =IFERROR((AVERAGE(podatki!G5+podatki!H5+podatki!J5)-podatki!L5),"Error") -> 12.143 | D10: =RANK(Sheet3!B10,Sheet3!$B$7:$B$155) -> 4 | E10: =RANK(Sheet3!C10,Sheet3!$C$7:$C$155) -> 17 | F10: =E10-D10 -> 13 | I10: 2 | J10: Luxembourg | K10: Denmark
A11: Netherlands | B11: 7464 | C11: =IFERROR((AVERAGE(podatki!G6+podatki!H6+podatki!J6)-podatki!L6),"Error") -> 12.449 | D11: =RANK(Sheet3!B11,Sheet3!$B$7:$B$155) -> 5 | E11: =RANK(Sheet3!C11,Sheet3!$C$7:$C$155) -> 9 | F11: =E11-D11 -> 4 | I11: 3 | J11: Ireland | K11: Switzerland
A12: Norway | B12: 7392 | C12: =IFERROR((AVERAGE(podatki!G7+podatki!H7+podatki!J7)-podatki!L7),"Error") -> 12.697 | D12: =RANK(Sheet3!B12,Sheet3!$B$7:$B$155) -> 6 | E12: =RANK(Sheet3!C12,Sheet3!$C$7:$C$155) -> 4 | F12: =E12-D12 -> -2 | I12: 4 | J12: Norway | K12: Iceland
A13: Sweden | B13: 7363 | C13: =IFERROR((AVERAGE(podatki!G8+podatki!H8+podatki!J8)-podatki!L8),"Error") -> 12.509 | D13: =RANK(Sheet3!B13,Sheet3!$B$7:$B$155) -> 7 | E13: =RANK(Sheet3!C13,Sheet3!$C$7:$C$155) -> 7 | F13: =E13-D13 -> 0 | I13: 5 | J13: Switzerland | K13: Netherlands
A14: Luxembourg | B14: 7324 | C14: =IFERROR((AVERAGE(podatki!G9+podatki!H9+podatki!J9)-podatki!L9),"Error") -> 13.076 | D14: =RANK(Sheet3!B14,Sheet3!$B$7:$B$155) -> 8 | E14: =RANK(Sheet3!C14,Sheet3!$C$7:$C$155) -> 2 | F14: =E14-D14 -> -6 | I14: 6 | J14: Denmark | K14: Norway
A15: New Zealand | B15: 7277 | C15: =IFERROR((AVERAGE(podatki!G10+podatki!H10+podatki!J10)-podatki!L10),"Error") -> 12.278 | D15: =RANK(Sheet3!B15,Sheet3!$B$7:$B$155) -> 9 | E15: =RANK(Sheet3!C15,Sheet3!$C$7:$C$155) -> 10 | F15: =E15-D15 -> 1 | I15: 7 | J15: Sweden | K15: Sweden
A16: Austria | B16: 7268 | C16: =IFERROR((AVERAGE(podatki!G11+podatki!H11+podatki!J11)-podatki!L11),"Error") -> 12.267 | D16: =RANK(Sheet3!B16,Sheet3!$B$7:$B$155) -> 10 | E16: =RANK(Sheet3!C16,Sheet3!$C$7:$C$155) -> 12 | F16: =E16-D16 -> 2 | I16: 8 | J16: Finland | K16: Luxembourg
A17: Australia | B17: 7183 | C17: =IFERROR((AVERAGE(podatki!G12+podatki!H12+podatki!J12)-podatki!L12),"Error") -> 12.208 | D17: =RANK(Sheet3!B17,Sheet3!$B$7:$B$155) -> 11 | E17: =RANK(Sheet3!C17,Sheet3!$C$7:$C$155) -> 13 | F17: =E17-D17 -> 2 | I17: 9 | J17: Netherlands | K17: New Zealand
A18: Israel | B18: 7157 | C18: =IFERROR((AVERAGE(podatki!G13+podatki!H13+podatki!J13)-podatki!L13),"Error") -> 11.561 | D18: =RANK(Sheet3!B18,Sheet3!$B$7:$B$155) -> 12 | E18: =RANK(Sheet3!C18,Sheet3!$C$7:$C$155) -> 31 | F18: =E18-D18 -> 19 | I18: 10 | J18: New Zealand | K18: Austria
A19: Germany | B19: 7155 | C19: =IFERROR((AVERAGE(podatki!G14+podatki!H14+podatki!J14)-podatki!L14),"Error") -> 12.191 | D19: =RANK(Sheet3!B19,Sheet3!$B$7:$B$155) -> 13 | E19: =RANK(Sheet3!C19,Sheet3!$C$7:$C$155) -> 15 | F19: =E19-D19 -> 2
A20: Canada | B20: 7103 | C20: =IFERROR((AVERAGE(podatki!G15+podatki!H15+podatki!J15)-podatki!L15),"Error") -> 12.202 | D20: =RANK(Sheet3!B20,Sheet3!$B$7:$B$155) -> 14 | E20: =RANK(Sheet3!C20,Sheet3!$C$7:$C$155) -> 14 | F20: =E20-D20 -> 0
A21: Ireland | B21: 7085 | C21: =IFERROR((AVERAGE(podatki!G16+podatki!H16+podatki!J16)-podatki!L16),"Error") -> 12.805 | D21: =RANK(Sheet3!B21,Sheet3!$B$7:$B$155) -> 15 | E21: =RANK(Sheet3!C21,Sheet3!$C$7:$C$155) -> 3 | F21: =E21-D21 -> -12
A22: Costa Rica | B22: 7069 | C22: =IFERROR((AVERAGE(podatki!G17+podatki!H17+podatki!J17)-podatki!L17),"Error") -> 10.896 | D22: =RANK(Sheet3!B22,Sheet3!$B$7:$B$155) -> 16 | E22: =RANK(Sheet3!C22,Sheet3!$C$7:$C$155) -> 51 | F22: =E22-D22 -> 35
A23: United Kingdom | B23: 7064 | C23: =IFERROR((AVERAGE(podatki!G18+podatki!H18+podatki!J18)-podatki!L18),"Error") -> 12.041 | D23: =RANK(Sheet3!B23,Sheet3!$B$7:$B$155) -> 17 | E23: =RANK(Sheet3!C23,Sheet3!$C$7:$C$155) -> 19 | F23: =E23-D23 -> 2
A24: Czech Republic | B24: 6965 | C24: =IFERROR((AVERAGE(podatki!G19+podatki!H19+podatki!J19)-podatki!L19),"Error") -> 11.493 | D24: =RANK(Sheet3!B24,Sheet3!$B$7:$B$155) -> 18 | E24: =RANK(Sheet3!C24,Sheet3!$C$7:$C$155) -> 33 | F24: =E24-D24 -> 15
A25: United States | B25: 6951 | C25: =IFERROR((AVERAGE(podatki!G20+podatki!H20+podatki!J20)-podatki!L20),"Error") -> 12.082 | D25: =RANK(Sheet3!B25,Sheet3!$B$7:$B$155) -> 19 | E25: =RANK(Sheet3!C25,Sheet3!$C$7:$C$155) -> 18 | F25: =E25-D25 -> -1
A26: Belgium | B26: 6834 | C26: =IFERROR((AVERAGE(podatki!G21+podatki!H21+podatki!J21)-podatki!L21),"Error") -> 11.866 | D26: =RANK(Sheet3!B26,Sheet3!$B$7:$B$155) -> 20 | E26: =RANK(Sheet3!C26,Sheet3!$C$7:$C$155) -> 22 | F26: =E26-D26 -> 2
A27: France | B27: 6690 | C27: =IFERROR((AVERAGE(podatki!G22+podatki!H22+podatki!J22)-podatki!L22),"Error") -> 11.897 | D27: =RANK(Sheet3!B27,Sheet3!$B$7:$B$155) -> 21 | E27: =RANK(Sheet3!C27,Sheet3!$C$7:$C$155) -> 20 | F27: =E27-D27 -> -1
A28: Bahrain | B28: 6647 | C28: =IFERROR((AVERAGE(podatki!G23+podatki!H23+podatki!J23)-podatki!L23),"Error") -> 11.734 | D28: =RANK(Sheet3!B28,Sheet3!$B$7:$B$155) -> 22 | E28: =RANK(Sheet3!C28,Sheet3!$C$7:$C$155) -> 27 | F28: =E28-D28 -> 5
A29: Malta | B29: 6602 | C29: =IFERROR((AVERAGE(podatki!G24+podatki!H24+podatki!J24)-podatki!L24),"Error") -> 11.879 | D29: =RANK(Sheet3!B29,Sheet3!$B$7:$B$155) -> 23 | E29: =RANK(Sheet3!C29,Sheet3!$C$7:$C$155) -> 21 | F29: =E29-D29 -> -2
A30: Taiwan Province of China | B30: 6584 | C30: =IFERROR((AVERAGE(podatki!G25+podatki!H25+podatki!J25)-podatki!L25),"Error") -> 11.832 | D30: =RANK(Sheet3!B30,Sheet3!$B$7:$B$155) -> 24 | E30: =RANK(Sheet3!C30,Sheet3!$C$7:$C$155) -> 23 | F30: =E30-D30 -> -1
... A155: Afghanistan | B155: 2523 | C155: =IFERROR((AVERAGE(podatki!G150+podatki!H150+podatki!J150)-podatki!L150),"Error") -> 7.616 | D155: =RANK(Sheet3!B155,Sheet3!$B$7:$B$155) -> 149 | E155: =RANK(Sheet3!C155,Sheet3!$C$7:$C$155) -> 147 | F155: =E155-D155 -> -2

Sheet Sheet4
A1: 🔹 4. Scenariji in napovedi
A2: ✅ Cilj: Predvidi spremembe in scenarije
A3: 1. Kaj se zgodi z Ladder score, če se GDP poveča za 20 % v Afriki?
A4: 2. Ustvari hipotetično lestvico: Če bi v vsaki državi izboljšali “Freedom” na 0.95
A5: 🔧 Orodja:
A6: FORECAST, IF, WHATIF analysis, GOAL SEEK
A7: Vzemi samo države določene regije z FILTER
B9: =COUNTA(B32:B145) -> 114
A11: Finland | B11: Western Europe | C11: 10775 | D11: 7842 | I11: Burundi | J11: 7.962 | K11: 3.7020687
A12: Denmark | B12: Western Europe | C12: 10933 | D12: 7620 | I12: India | J12: 10.506 | K12: 5.3890162
A13: Switzerland | B13: Western Europe | C13: 11117 | D13: 7571 | I13: Sierra Leone | J13: 8.9208 | K13: 4.3293164
A14: Iceland | B14: Western Europe | C14: 10878 | D14: 7554 | I14: Zambia | J14: 9.774 | K14: 5.0352374
A15: Netherlands | B15: Western Europe | C15: 10932 | D15: 7464 | I15: Togo | J15: 8.8344 | K15: 4.0938899
A16: Norway | B16: Western Europe | C16: 11053 | D16: 7392 | I16: Madagascar | J16: 8.8752 | K16: 4.3611118
A17: Sweden | B17: Western Europe | C17: 10867 | D17: 7363 | I17: Mauritania | J17: 10.2504 | K17: 4.9752801
A18: Luxembourg | B18: Western Europe | C18: 11647 | D18: 7324 | I18: Ethiopia | J18: 9.2328 | K18: 5.1041801
A19: New Zealand | B19: North America and ANZ | C19: 10643 | D19: 7277 | I19: Egypt | J19: 11.2404 | K19: 5.5986704
A20: Austria | B20: Western Europe | C20: 10906 | D20: 7268 | I20: Comoros | J20: 9.6372 | K20: 4.403225
A21: Australia | B21: North America and ANZ | C21: 10796 | D21: 7183 | I21: Swaziland | J21: 10.878 | K21: 5.0550836
B22: Country name | C22: GDP per capita | D22: Ladder score | E22: New GDP
B23: Germany | C23: 10873 | D23: 7155 | I23: Chad | J23: 8.8368 | K23: 3.925041
B24: Canada | C24: 10776 | D24: 7103 | I24: Jordan | J24: 11.0184 | K24: 5.8022654
B25: Ireland | C25: 11342 | D25: 7085 | I25: Myanmar | J25: 10.2492 | K25: 5.9005734
B26: Costa Rica | C26: 9880 | D26: 7069 | I26: Palestinian Territories | J26: 10.182 | K26: 5.2968574
B27: United Kingdom | C27: 10707 | D27: 7064 | I27: Namibia | J27: 10.9932 | K27: 5.4606749
B28: Czech Republic | C28: 10556 | D28: 6965 | I28: Lebanon | J28: 11.5512 | K28: 5.617566
B29: United States | C29: 11023 | D29: 6951 | I29: Tunisia | J29: 11.1192 | K29: 5.3370675
B30: Belgium | C30: 10823 | D30: 6834 | I30: Kenya | J30: 10.0332 | K30: 5.281591
B31: France | C31: 10704 | D31: 6690 | I31: Liberia | J31: 8.7456 | K31: 4.6835511
B32: Mauritius | C32: =10008/(1000) -> 10.008 | D32: =6049/(1000) -> 6.049 | E32: =1.2*C32 -> 12.0096
B33: Malta | C33: =10674/(1000) -> 10.674 | D33: =6602/(1000) -> 6.602 | I33: Iran | J33: 11.5008 | K33: 5.6140474
B34: Taiwan Province of China | C34: =10871/(1000) -> 10.871 | D34: =6584/(1000) -> 6.584 | I34: Mali | J34: 9.2928 | K34: 4.6153495
B35: Botswana | C35: =9782/(1000) -> 9.782 | D35: =3467/(1000) -> 3.467 | E35: =1.2*C35 -> 11.7384
B36: Libya | C36: =9622/(1000) -> 9.622 | D36: =5410/(1000) -> 5.41 | E36: =1.2*C36 -> 11.5464
B37: Spain | C37: =10571/(1000) -> 10.571 | D37: =6491/(1000) -> 6.491 | I37: Cambodia | J37: 10.032 | K37: 5.7699968
B38: Italy | C38: =10623/(1000) -> 10.623 | D38: =6483/(1000) -> 6.483 | I38: Burkina Faso | J38: 9.2136 | K38: 4.584186
B39: Slovenia | C39: =10529/(1000) -> 10.529 | D39: =6461/(1000) -> 6.461 | I39: Gabon | J39: 11.5236 | K39: 5.6105375
B40: Guatemala | C40: =9053/(1000) -> 9.053 | D40: =6435/(1000) -> 6.435 | I40: Iraq | J40: 11.088 | K40: 5.2626454
B41: Uruguay | C41: =9966/(1000) -> 9.966 | D41: =6431/(1000) -> 6.431 | I41: Ukraine | J41: 11.3232 | K41: 5.9855118
B42: Singapore | C42: =11488/(1000) -> 11.488 | D42: =6377/(1000) -> 6.377 | I42: Algeria | J42: 11.2104 | K42: 5.3675607
...

Sheet Sheet7
A1: Regional indicator | B1: Country name | C1: Original happiness score | D1: New happiness score
A2: Western Europe | B2: Finland | C2: =7842/(1000) -> 7.842 | D2: 7.6803345 | E2: =-2.2372+0.2795*Sheet5!D2+ 2.4762*Sheet5!E2+ 0.0303*Sheet5!F2+ 2.0105*0.95+ 0.3644*Sheet5!H2- 0.6051*Sheet5!I2 -> 7.0800225
A3: Western Europe | B3: Denmark | C3: =7620/(1000) -> 7.62 | D3: 7.7993851 | E3: =-2.2372+0.2795*Sheet5!D3+ 2.4762*Sheet5!E3+ 0.0303*Sheet5!F3+ 2.0105*0.95+ 0.3644*Sheet5!H3- 0.6051*Sheet5!I3 -> 7.1962724
A4: Western Europe | B4: Switzerland | C4: =7571/(1000) -> 7.571 | D4: 7.7584125 | E4: =-2.2372+0.2795*Sheet5!D4+ 2.4762*Sheet5!E4+ 0.0303*Sheet5!F4+ 2.0105*0.95+ 0.3644*Sheet5!H4- 0.6051*Sheet5!I4 -> 7.1992977
A5: Western Europe | B5: Iceland | C5: =7554/(1000) -> 7.554 | D5: 7.628385 | E5: =-2.2372+0.2795*Sheet5!D5+ 2.4762*Sheet5!E5+ 0.0303*Sheet5!F5+ 2.0105*0.95+ 0.3644*Sheet5!H5- 0.6051*Sheet5!I5 -> 7.0102523
A6: Western Europe | B6: Netherlands | C6: =7464/(1000) -> 7.464 | D6: 7.6505259 | E6: =-2.2372+0.2795*Sheet5!D6+ 2.4762*Sheet5!E6+ 0.0303*Sheet5!F6+ 2.0105*0.95+ 0.3644*Sheet5!H6- 0.6051*Sheet5!I6 -> 7.1138156
A7: Western Europe | B7: Norway | C7: =7392/(1000) -> 7.392 | D7: 7.8538532 | E7: =-2.2372+0.2795*Sheet5!D7+ 2.4762*Sheet5!E7+ 0.0303*Sheet5!F7+ 2.0105*0.95+ 0.3644*Sheet5!H7- 0.6051*Sheet5!I7 -> 7.2158855
A8: Western Europe | B8: Sweden | C8: =7363/(1000) -> 7.363 | D8: 7.7110248 | E8: =-2.2372+0.2795*Sheet5!D8+ 2.4762*Sheet5!E8+ 0.0303*Sheet5!F8+ 2.0105*0.95+ 0.3644*Sheet5!H8- 0.6051*Sheet5!I8 -> 7.113612
A9: Western Europe | B9: Luxembourg | C9: =7324/(1000) -> 7.324 | D9: 7.6949387 | E9: =-2.2372+0.2795*Sheet5!D9+ 2.4762*Sheet5!E9+ 0.0303*Sheet5!F9+ 2.0105*0.95+ 0.3644*Sheet5!H9- 0.6051*Sheet5!I9 -> 7.1303229
A10: North America and ANZ | B10: New Zealand | C10: =7277/(1000) -> 7.277 | D10: 7.6740697 | E10: =-2.2372+0.2795*Sheet5!D10+ 2.4762*Sheet5!E10+ 0.0303*Sheet5!F10+ 2.0105*0.95+ 0.3644*Sheet5!H10- 0.6051*Sheet5!I10 -> 7.1213465
A11: Western Europe | B11: Austria | C11: =7268/(1000) -> 7.268 | D11: 7.5042189 | E11: =-2.2372+0.2795*Sheet5!D11+ 2.4762*Sheet5!E11+ 0.0303*Sheet5!F11+ 2.0105*0.95+ 0.3644*Sheet5!H11- 0.6051*Sheet5!I11 -> 6.9790145
A12: North America and ANZ | B12: Australia | C12: =7183/(1000) -> 7.183 | D12: 7.5786588 | E12: =-2.2372+0.2795*Sheet5!D12+ 2.4762*Sheet5!E12+ 0.0303*Sheet5!F12+ 2.0105*0.95+ 0.3644*Sheet5!H12- 0.6051*Sheet5!I12 -> 7.0475404
A13: Middle East and North Africa | B13: Algeria | C13: =7157/(1000) -> 7.157 | D13: 5.3675607
A14: Western Europe | B14: Germany | C14: =7155/(1000) -> 7.155 | D14: 7.3272127 | E14: =-2.2372+0.2795*Sheet5!D14+ 2.4762*Sheet5!E14+ 0.0303*Sheet5!F14+ 2.0105*0.95+ 0.3644*Sheet5!H14- 0.6051*Sheet5!I14 -> 6.8701995
A15: North America and ANZ | B15: Canada | C15: =7103/(1000) -> 7.103 | D15: 7.5270942 | E15: =-2.2372+0.2795*Sheet5!D15+ 2.4762*Sheet5!E15+ 0.0303*Sheet5!F15+ 2.0105*0.95+ 0.3644*Sheet5!H15- 0.6051*Sheet5!I15 -> 6.9950833
A16: Western Europe | B16: Ireland | C16: =7085/(1000) -> 7.085 | D16: 7.6812252 | E16: =-2.2372+0.2795*Sheet5!D16+ 2.4762*Sheet5!E16+ 0.0303*Sheet5!F16+ 2.0105*0.95+ 0.3644*Sheet5!H16- 0.6051*Sheet5!I16 -> 7.1899529
A17: Latin America and Caribbean | B17: Costa Rica | C17: =7069/(1000) -> 7.069 | D17: 6.7886329 | E17: =-2.2372+0.2795*Sheet5!D17+ 2.4762*Sheet5!E17+ 0.0303*Sheet5!F17+ 2.0105*0.95+ 0.3644*Sheet5!H17- 0.6051*Sheet5!I17 -> 6.2685089
A18: Western Europe | B18: United Kingdom | C18: =7064/(1000) -> 7.064 | D18: 7.3976324 | E18: =-2.2372+0.2795*Sheet5!D18+ 2.4762*Sheet5!E18+ 0.0303*Sheet5!F18+ 2.0105*0.95+ 0.3644*Sheet5!H18- 0.6051*Sheet5!I18 -> 6.9820666
A19: Central and Eastern Europe | B19: Czech Republic | C19: =6965/(1000) -> 6.965 | D19: 6.9176829 | E19: =-2.2372+0.2795*Sheet5!D19+ 2.4762*Sheet5!E19+ 0.0303*Sheet5!F19+ 2.0105*0.95+ 0.3644*Sheet5!H19- 0.6051*Sheet5!I19 -> 6.5125685
A20: North America and ANZ | B20: United States | C20: =6951/(1000) -> 6.951 | D20: 7.1006181 | E20: =-2.2372+0.2795*Sheet5!D20+ 2.4762*Sheet5!E20+ 0.0303*Sheet5!F20+ 2.0105*0.95+ 0.3644*Sheet5!H20- 0.6051*Sheet5!I20 -> 6.7116189
A21: Western Europe | B21: Belgium | C21: =6834/(1000) -> 6.834 | D21: 6.9514748 | E21: =-2.2372+0.2795*Sheet5!D21+ 2.4762*Sheet5!E21+ 0.0303*Sheet5!F21+ 2.0105*0.95+ 0.3644*Sheet5!H21- 0.6051*Sheet5!I21 -> 6.6822226
A22: Western Europe | B22: France | C22: =6690/(1000) -> 6.69 | D22: 7.1812541 | E22: =-2.2372+0.2795*Sheet5!D22+ 2.4762*Sheet5!E22+ 0.0303*Sheet5!F22+ 2.0105*0.95+ 0.3644*Sheet5!H22- 0.6051*Sheet5!I22 -> 6.8402445
A23: Sub-Saharan Africa | B23: Benin | C23: =6647/(1000) -> 6.647 | D23: 4.4534333
A24: Western Europe | B24: Malta | C24: =6602/(1000) -> 6.602 | D24: 7.3529302 | E24: =-2.2372+0.2795*Sheet5!D24+ 2.4762*Sheet5!E24+ 0.0303*Sheet5!F24+ 2.0105*0.95+ 0.3644*Sheet5!H24- 0.6051*Sheet5!I24 -> 6.8024951
A25: East Asia | B25: Taiwan Province of China | C25: =6584/(1000) -> 6.584 | D25: 6.8558879 | E25: =-2.2372+0.2795*Sheet5!D25+ 2.4762*Sheet5!E25+ 0.0303*Sheet5!F25+ 2.0105*0.95+ 0.3644*Sheet5!H25- 0.6051*Sheet5!I25 -> 6.581942
A26: Sub-Saharan Africa | B26: Botswana | C26: =6561/(1000) -> 6.561 | D26: 5.8631988
A27: Sub-Saharan Africa | B27: Burkina Faso | C27: =6494/(1000) -> 6.494 | D27: 4.584186
A28: Western Europe | B28: Spain | C28: =6491/(1000) -> 6.491 | D28: 6.9292164 | E28: =-2.2372+0.2795*Sheet5!D28+ 2.4762*Sheet5!E28+ 0.0303*Sheet5!F28+ 2.0105*0.95+ 0.3644*Sheet5!H28- 0.6051*Sheet5!I28 -> 6.718282
A29: Western Europe | B29: Italy | C29: =6483/(1000) -> 6.483 | D29: 6.5796005 | E29: =-2.2372+0.2795*Sheet5!D29+ 2.4762*Sheet5!E29+ 0.0303*Sheet5!F29+ 2.0105*0.95+ 0.3644*Sheet5!H29- 0.6051*Sheet5!I29 -> 6.5024733
A30: Central and Eastern Europe | B30: Slovenia | C30: =6461/(1000) -> 6.461 | D30: 7.1885337 | E30: =-2.2372+0.2795*Sheet5!D30+ 2.4762*Sheet5!E30+ 0.0303*Sheet5!F30+ 2.0105*0.95+ 0.3644*Sheet5!H30- 0.6051*Sheet5!I30 -> 6.6019731
A31: Latin America and Caribbean | B31: Guatemala | C31: =6435/(1000) -> 6.435 | D31: 6.1192675 | E31: =-2.2372+0.2795*Sheet5!D31+ 2.4762*Sheet5!E31+ 0.0303*Sheet5!F31+ 2.0105*0.95+ 0.3644*Sheet5!H31- 0.6051*Sheet5!I31 -> 5.7016668
A32: Latin America and Caribbean | B32: Uruguay | C32: =6431/(1000) -> 6.431 | D32: 6.9004856 | E32: =-2.2372+0.2795*Sheet5!D32+ 2.4762*Sheet5!E32+ 0.0303*Sheet5!F32+ 2.0105*0.95+ 0.3644*Sheet5!H32- 0.6051*Sheet5!I32 -> 6.4519532
A33: Southeast Asia | B33: Singapore | C33: =6377/(1000) -> 6.377 | D33: 8.0208302 | E33: =-2.2372+0.2795*Sheet5!D33+ 2.4762*Sheet5!E33+ 0.0303*Sheet5!F33+ 2.0105*0.95+ 0.3644*Sheet5!H33- 0.6051*Sheet5!I33 -> 7.4248925
A34: Central and Eastern Europe | B34: Kosovo | C34: =6372/(1000) -> 6.372 | D34: 6.1404499 | E34: =-2.2372+0.2795*Sheet5!D34+ 2.4762*Sheet5!E34+ 0.0303*Sheet5!F34+ 2.0105*0.95+ 0.3644*Sheet5!H34- 0.6051*Sheet5!I34 -> 5.7824242
A35: Central and Eastern Europe | B35: Slovakia | C35: =6331/(1000) -> 6.331 | D35: 6.5986874 | E35: =-2.2372+0.2795*Sheet5!D35+ 2.4762*Sheet5!E35+ 0.0303*Sheet5!F35+ 2.0105*0.95+ 0.3644*Sheet5!H35- 0.6051*Sheet5!I35 -> 6.3889923
A36: Latin America and Caribbean | B36: Brazil | C36: =6330/(1000) -> 6.33 | D36: 6.3100585 | E36: =-2.2372+0.2795*Sheet5!D36+ 2.4762*Sheet5!E36+ 0.0303*Sheet5!F36+ 2.0105*0.95+ 0.3644*Sheet5!H36- 0.6051*Sheet5!I36 -> 6.0682372
A37: Latin America and Caribbean | B37: Mexico | C37: =6317/(1000) -> 6.317 | D37: 6.4017292 | E37: =-2.2372+0.2795*Sheet5!D37+ 2.4762*Sheet5!E37+ 0.0303*Sheet5!F37+ 2.0105*0.95+ 0.3644*Sheet5!H37- 0.6051*Sheet5!I37 -> 6.0275351
A38: Latin America and Caribbean | B38: Jamaica | C38: =6309/(1000) -> 6.309 | D38: 6.2651756 | E38: =-2.2372+0.2795*Sheet5!D38+ 2.4762*Sheet5!E38+ 0.0303*Sheet5!F38+ 2.0105*0.95+ 0.3644*Sheet5!H38- 0.6051*Sheet5!I38 -> 5.8723082
A39: Central and Eastern Europe | B39: Lithuania | C39: =6255/(1000) -> 6.255 | D39: 6.6372941 | E39: =-2.2372+0.2795*Sheet5!D39+ 2.4762*Sheet5!E39+ 0.0303*Sheet5!F39+ 2.0105*0.95+ 0.3644*Sheet5!H39- 0.6051*Sheet5!I39 -> 6.4062585
A40: Western Europe | B40: Cyprus | C40: =6223/(1000) -> 6.223 | D40: 6.5528533 | E40: =-2.2372+0.2795*Sheet5!D40+ 2.4762*Sheet5!E40+ 0.0303*Sheet5!F40+ 2.0105*0.95+ 0.3644*Sheet5!H40- 0.6051*Sheet5!I40 -> 6.3376184
...

Sheet Sheet5
A1: Regional indicator | B1: Country name | C1: Ladder score | D1: Logged GDP per capita | E1: Social support | F1: Healthy life expectancy | G1: Freedom to make life choices | H1: Generosity | I1: Perceptions of corruption | J1: Calculated happiness score | K1: Difference | L1: New logged GDP | M1: New happiness score | N1: New freedom-happiness score | O1: Difference between normal and freedom happiness score
A2: Western Europe | B2: Finland | C2: =7842/(1000) -> 7.842 | D2: =10775/(1000) -> 10.775 | E2: 0.954 | F2: =72000/(1000) -> 72 | G2: 0.949 | H2: -0.098 | I2: 0.186 | J2: =-2.2372+0.2795*D2+ 2.4762*E2+ 0.0303*F2+ 2.0105*G2+ 0.3644*H2- 0.6051*I2 -> 7.078012 | K2: =ABS(C2-J2) -> 0.763988 | L2: =1.2*D2 -> 12.93 | M2: =-2.2372+0.2795*L2+ 2.4762*E2+ 0.0303*F2+ 2.0105*G2+ 0.3644*H2- 0.6051*I2 -> 7.6803345 | N2: =-2.2372+0.2795*Sheet5!D2+ 2.4762*Sheet5!E2+ 0.0303*Sheet5!F2+ 2.0105*0.95+ 0.3644*Sheet5!H2- 0.6051*Sheet5!I2 -> 7.0800225 | O2: =C2-N2 -> 0.7619775
A3: Western Europe | B3: Denmark | C3: =7620/(1000) -> 7.62 | D3: =10933/(1000) -> 10.933 | E3: 0.954 | F3: =72700/(1000) -> 72.7 | G3: 0.946 | H3: 0.03 | I3: 0.179 | J3: =-2.2372+0.2795*D3+ 2.4762*E3+ 0.0303*F3+ 2.0105*G3+ 0.3644*H3- 0.6051*I3 -> 7.1882304 | K3: =ABS(C3-J3) -> 0.4317696 | L3: =1.2*D3 -> 13.1196 | M3: =-2.2372+0.2795*L3+ 2.4762*E3+ 0.0303*F3+ 2.0105*G3+ 0.3644*H3- 0.6051*I3 -> 7.7993851 | N3: =-2.2372+0.2795*D3+ 2.4762*E3+ 0.0303*F3+ 2.0105*0.95+ 0.3644*H3- 0.6051*I3 -> 7.1962724 | O3: =C3-N3 -> 0.4237276
A4: Western Europe | B4: Switzerland | C4: =7571/(1000) -> 7.571 | D4: =11117/(1000) -> 11.117 | E4: 0.942 | F4: =74400/(1000) -> 74.4 | G4: 0.919 | H4: 0.025 | I4: 0.292 | J4: =-2.2372+0.2795*D4+ 2.4762*E4+ 0.0303*F4+ 2.0105*G4+ 0.3644*H4- 0.6051*I4 -> 7.1369722 | K4: =ABS(C4-J4) -> 0.4340278 | L4: =1.2*D4 -> 13.3404 | M4: =-2.2372+0.2795*L4+ 2.4762*E4+ 0.0303*F4+ 2.0105*G4+ 0.3644*H4- 0.6051*I4 -> 7.7584125 | N4: =-2.2372+0.2795*D4+ 2.4762*E4+ 0.0303*F4+ 2.0105*0.95+ 0.3644*H4- 0.6051*I4 -> 7.1992977 | O4: =C4-N4 -> 0.3717023
A5: Western Europe | B5: Iceland | C5: =7554/(1000) -> 7.554 | D5: =10878/(1000) -> 10.878 | E5: 0.983 | F5: =73000/(1000) -> 73 | G5: 0.955 | H5: 0.16 | I5: 0.673 | J5: =-2.2372+0.2795*D5+ 2.4762*E5+ 0.0303*F5+ 2.0105*G5+ 0.3644*H5- 0.6051*I5 -> 7.0203048 | K5: =ABS(C5-J5) -> 0.5336952 | L5: =1.2*D5 -> 13.0536 | M5: =-2.2372+0.2795*L5+ 2.4762*E5+ 0.0303*F5+ 2.0105*G5+ 0.3644*H5- 0.6051*I5 -> 7.628385 | N5: =-2.2372+0.2795*D5+ 2.4762*E5+ 0.0303*F5+ 2.0105*0.95+ 0.3644*H5- 0.6051*I5 -> 7.0102523 | O5: =C5-N5 -> 0.5437477
A6: Western Europe | B6: Netherlands | C6: =7464/(1000) -> 7.464 | D6: =10932/(1000) -> 10.932 | E6: 0.942 | F6: =72400/(1000) -> 72.4 | G6: 0.913 | H6: 0.175 | I6: 0.338 | J6: =-2.2372+0.2795*D6+ 2.4762*E6+ 0.0303*F6+ 2.0105*G6+ 0.3644*H6- 0.6051*I6 -> 7.0394271 | K6: =ABS(C6-J6) -> 0.4245729 | L6: =1.2*D6 -> 13.1184 | M6: =-2.2372+0.2795*L6+ 2.4762*E6+ 0.0303*F6+ 2.0105*G6+ 0.3644*H6- 0.6051*I6 -> 7.6505259 | N6: =-2.2372+0.2795*D6+ 2.4762*E6+ 0.0303*F6+ 2.0105*0.95+ 0.3644*H6- 0.6051*I6 -> 7.1138156 | O6: =C6-N6 -> 0.3501844
A7: Western Europe | B7: Norway | C7: =7392/(1000) -> 7.392 | D7: =11053/(1000) -> 11.053 | E7: 0.954 | F7: =73300/(1000) -> 73.3 | G7: 0.96 | H7: 0.093 | I7: 0.27 | J7: =-2.2372+0.2795*D7+ 2.4762*E7+ 0.0303*F7+ 2.0105*G7+ 0.3644*H7- 0.6051*I7 -> 7.2359905 | K7: =ABS(C7-J7) -> 0.1560095 | L7: =1.2*D7 -> 13.2636 | M7: =-2.2372+0.2795*L7+ 2.4762*E7+ 0.0303*F7+ 2.0105*G7+ 0.3644*H7- 0.6051*I7 -> 7.8538532 | N7: =-2.2372+0.2795*D7+ 2.4762*E7+ 0.0303*F7+ 2.0105*0.95+ 0.3644*H7- 0.6051*I7 -> 7.2158855 | O7: =C7-N7 -> 0.1761145
A8: Western Europe | B8: Sweden | C8: =7363/(1000) -> 7.363 | D8: =10867/(1000) -> 10.867 | E8: 0.934 | F8: =72700/(1000) -> 72.7 | G8: 0.945 | H8: 0.086 | I8: 0.237 | J8: =-2.2372+0.2795*D8+ 2.4762*E8+ 0.0303*F8+ 2.0105*G8+ 0.3644*H8- 0.6051*I8 -> 7.1035595 | K8: =ABS(C8-J8) -> 0.2594405 | L8: =1.2*D8 -> 13.0404 | M8: =-2.2372+0.2795*L8+ 2.4762*E8+ 0.0303*F8+ 2.0105*G8+ 0.3644*H8- 0.6051*I8 -> 7.7110248 | N8: =-2.2372+0.2795*D8+ 2.4762*E8+ 0.0303*F8+ 2.0105*0.95+ 0.3644*H8- 0.6051*I8 -> 7.113612 | O8: =C8-N8 -> 0.249388
A9: Western Europe | B9: Luxembourg | C9: =7324/(1000) -> 7.324 | D9: =11647/(1000) -> 11.647 | E9: 0.908 | F9: =72600/(1000) -> 72.6 | G9: 0.907 | H9: -0.034 | I9: 0.386 | J9: =-2.2372+0.2795*D9+ 2.4762*E9+ 0.0303*F9+ 2.0105*G9+ 0.3644*H9- 0.6051*I9 -> 7.0438714 | K9: =ABS(C9-J9) -> 0.2801286 | L9: =1.2*D9 -> 13.9764 | M9: =-2.2372+0.2795*L9+ 2.4762*E9+ 0.0303*F9+ 2.0105*G9+ 0.3644*H9- 0.6051*I9 -> 7.6949387 | N9: =-2.2372+0.2795*D9+ 2.4762*E9+ 0.0303*F9+ 2.0105*0.95+ 0.3644*H9- 0.6051*I9 -> 7.1303229 | O9: =C9-N9 -> 0.1936771
A10: North America and ANZ | B10: New Zealand | C10: =7277/(1000) -> 7.277 | D10: =10643/(1000) -> 10.643 | E10: 0.948 | F10: =73400/(1000) -> 73.4 | G10: 0.929 | H10: 0.134 | I10: 0.242 | J10: =-2.2372+0.2795*D10+ 2.4762*E10+ 0.0303*F10+ 2.0105*G10+ 0.3644*H10- 0.6051*I10 -> 7.079126 | K10: =ABS(C10-J10) -> 0.197874 | L10: =1.2*D10 -> 12.7716 | M10: =-2.2372+0.2795*L10+ 2.4762*E10+ 0.0303*F10+ 2.0105*G10+ 0.3644*H10- 0.6051*I10 -> 7.6740697 | N10: =-2.2372+0.2795*D10+ 2.4762*E10+ 0.0303*F10+ 2.0105*0.95+ 0.3644*H10- 0.6051*I10 -> 7.1213465 | O10: =C10-N10 -> 0.1556535
A11: Western Europe | B11: Austria | C11: =7268/(1000) -> 7.268 | D11: =10906/(1000) -> 10.906 | E11: 0.934 | F11: =73300/(1000) -> 73.3 | G11: 0.908 | H11: 0.042 | I11: 0.481 | J11: =-2.2372+0.2795*D11+ 2.4762*E11+ 0.0303*F11+ 2.0105*G11+ 0.3644*H11- 0.6051*I11 -> 6.8945735 | K11: =ABS(C11-J11) -> 0.3734265 | L11: =1.2*D11 -> 13.0872 | M11: =-2.2372+0.2795*L11+ 2.4762*E11+ 0.0303*F11+ 2.0105*G11+ 0.3644*H11- 0.6051*I11 -> 7.5042189 | N11: =-2.2372+0.2795*D11+ 2.4762*E11+ 0.0303*F11+ 2.0105*0.95+ 0.3644*H11- 0.6051*I11 -> 6.9790145 | O11: =C11-N11 -> 0.2889855
A12: North America and ANZ | B12: Australia | C12: =7183/(1000) -> 7.183 | D12: =10796/(1000) -> 10.796 | E12: 0.94 | F12: =73900/(1000) -> 73.9 | G12: 0.914 | H12: 0.159 | I12: 0.442 | J12: =-2.2372+0.2795*D12+ 2.4762*E12+ 0.0303*F12+ 2.0105*G12+ 0.3644*H12- 0.6051*I12 -> 6.9751624 | K12: =ABS(C12-J12) -> 0.2078376 | L12: =1.2*D12 -> 12.9552 | M12: =-2.2372+0.2795*L12+ 2.4762*E12+ 0.0303*F12+ 2.0105*G12+ 0.3644*H12- 0.6051*I12 -> 7.5786588 | N12: =-2.2372+0.2795*D12+ 2.4762*E12+ 0.0303*F12+ 2.0105*0.95+ 0.3644*H12- 0.6051*I12 -> 7.0475404 | O12: =C12-N12 -> 0.1354596
A13: Middle East and North Africa | B13: Israel | C13: =7157/(1000) -> 7.157 | D13: =10575/(1000) -> 10.575 | E13: 0.939 | F13: =73503/(1000) -> 73.503 | G13: 0.8 | H13: 0.031 | I13: 0.753 | J13: =-2.2372+0.2795*D13+ 2.4762*E13+ 0.0303*F13+ 2.0105*G13+ 0.3644*H13- 0.6051*I13 -> 6.4348613 | K13: =ABS(C13-J13) -> 0.7221387 | L13: =1.2*D13 -> 12.69 | M13: =-2.2372+0.2795*L13+ 2.4762*E13+ 0.0303*F13+ 2.0105*G13+ 0.3644*H13- 0.6051*I13 -> 7.0260038 | N13: =-2.2372+0.2795*D13+ 2.4762*E13+ 0.0303*F13+ 2.0105*0.95+ 0.3644*H13- 0.6051*I13 -> 6.7364363 | O13: =C13-N13 -> 0.4205637
A14: Western Europe | B14: Germany | C14: =7155/(1000) -> 7.155 | D14: =10873/(1000) -> 10.873 | E14: 0.903 | F14: =72500/(1000) -> 72.5 | G14: 0.875 | H14: 0.011 | I14: 0.46 | J14: =-2.2372+0.2795*D14+ 2.4762*E14+ 0.0303*F14+ 2.0105*G14+ 0.3644*H14- 0.6051*I14 -> 6.719412 | K14: =ABS(C14-J14) -> 0.435588 | L14: =1.2*D14 -> 13.0476 | M14: =-2.2372+0.2795*L14+ 2.4762*E14+ 0.0303*F14+ 2.0105*G14+ 0.3644*H14- 0.6051*I14 -> 7.3272127 | N14: =-2.2372+0.2795*D14+ 2.4762*E14+ 0.0303*F14+ 2.0105*0.95+ 0.3644*H14- 0.6051*I14 -> 6.8701995 | O14: =C14-N14 -> 0.2848005
A15: North America and ANZ | B15: Canada | C15: =7103/(1000) -> 7.103 | D15: =10776/(1000) -> 10.776 | E15: 0.926 | F15: =73800/(1000) -> 73.8 | G15: 0.915 | H15: 0.089 | I15: 0.415 | J15: =-2.2372+0.2795*D15+ 2.4762*E15+ 0.0303*F15+ 2.0105*G15+ 0.3644*H15- 0.6051*I15 -> 6.9247158 | K15: =ABS(C15-J15) -> 0.1782842 | L15: =1.2*D15 -> 12.9312 | M15: =-2.2372+0.2795*L15+ 2.4762*E15+ 0.0303*F15+ 2.0105*G15+ 0.3644*H15- 0.6051*I15 -> 7.5270942 | N15: =-2.2372+0.2795*D15+ 2.4762*E15+ 0.0303*F15+ 2.0105*0.95+ 0.3644*H15- 0.6051*I15 -> 6.9950833 | O15: =C15-N15 -> 0.1079167
A16: Western Europe | B16: Ireland | C16: =7085/(1000) -> 7.085 | D16: =11342/(1000) -> 11.342 | E16: 0.947 | F16: =72400/(1000) -> 72.4 | G16: 0.879 | H16: 0.077 | I16: 0.363 | J16: =-2.2372+0.2795*D16+ 2.4762*E16+ 0.0303*F16+ 2.0105*G16+ 0.3644*H16- 0.6051*I16 -> 7.0472074 | K16: =ABS(C16-J16) -> 0.0377926 | L16: =1.2*D16 -> 13.6104 | M16: =-2.2372+0.2795*L16+ 2.4762*E16+ 0.0303*F16+ 2.0105*G16+ 0.3644*H16- 0.6051*I16 -> 7.6812252 | N16: =-2.2372+0.2795*D16+ 2.4762*E16+ 0.0303*F16+ 2.0105*0.95+ 0.3644*H16- 0.6051*I16 -> 7.1899529 | O16: =C16-N16 -> -0.1049529
A17: Latin America and Caribbean | B17: Costa Rica | C17: =7069/(1000) -> 7.069 | D17: =9880/(1000) -> 9.88 | E17: 0.891 | F17: =71400/(1000) -> 71.4 | G17: 0.934 | H17: -0.126 | I17: 0.809 | J17: =-2.2372+0.2795*D17+ 2.4762*E17+ 0.0303*F17+ 2.0105*G17+ 0.3644*H17- 0.6051*I17 -> 6.2363409 | K17: =ABS(C17-J17) -> 0.8326591 | L17: =1.2*D17 -> 11.856 | M17: =-2.2372+0.2795*L17+ 2.4762*E17+ 0.0303*F17+ 2.0105*G17+ 0.3644*H17- 0.6051*I17 -> 6.7886329 | N17: =-2.2372+0.2795*D17+ 2.4762*E17+ 0.0303*F17+ 2.0105*0.95+ 0.3644*H17- 0.6051*I17 -> 6.2685089 | O17: =C17-N17 -> 0.8004911
A18: Western Europe | B18: United Kingdom | C18: =7064/(1000) -> 7.064 | D18: =10707/(1000) -> 10.707 | E18: 0.934 | F18: =72500/(1000) -> 72.5 | G18: 0.859 | H18: 0.233 | I18: 0.459 | J18: =-2.2372+0.2795*D18+ 2.4762*E18+ 0.0303*F18+ 2.0105*G18+ 0.3644*H18- 0.6051*I18 -> 6.7991111 | K18: =ABS(C18-J18) -> 0.2648889 | L18: =1.2*D18 -> 12.8484 | M18: =-2.2372+0.2795*L18+ 2.4762*E18+ 0.0303*F18+ 2.0105*G18+ 0.3644*H18- 0.6051*I18 -> 7.3976324 | N18: =-2.2372+0.2795*D18+ 2.4762*E18+ 0.0303*F18+ 2.0105*0.95+ 0.3644*H18- 0.6051*I18 -> 6.9820666 | O18: =C18-N18 -> 0.0819334
A19: Central and Eastern Europe | B19: Czech Republic | C19: =6965/(1000) -> 6.965 | D19: =10556/(1000) -> 10.556 | E19: 0.947 | F19: =70807/(1000) -> 70.807 | G19: 0.858 | H19: -0.208 | I19: 0.868 | J19: =-2.2372+0.2795*D19+ 2.4762*E19+ 0.0303*F19+ 2.0105*G19+ 0.3644*H19- 0.6051*I19 -> 6.3276025 | K19: =ABS(C19-J19) -> 0.6373975 | L19: =1.2*D19 -> 12.6672 | M19: =-2.2372+0.2795*L19+ 2.4762*E19+ 0.0303*F19+ 2.0105*G19+ 0.3644*H19- 0.6051*I19 -> 6.9176829 | N19: =-2.2372+0.2795*D19+ 2.4762*E19+ 0.0303*F19+ 2.0105*0.95+ 0.3644*H19- 0.6051*I19 -> 6.5125685 | O19: =C19-N19 -> 0.4524315
A20: North America and ANZ | B20: United States | C20: =6951/(1000) -> 6.951 | D20: =11023/(1000) -> 11.023 | E20: 0.92 | F20: =68200/(1000) -> 68.2 | G20: 0.837 | H20: 0.098 | I20: 0.698 | J20: =-2.2372+0.2795*D20+ 2.4762*E20+ 0.0303*F20+ 2.0105*G20+ 0.3644*H20- 0.6051*I20 -> 6.4844324 | K20: =ABS(C20-J20) -> 0.4665676 | L20: =1.2*D20 -> 13.2276 | M20: =-2.2372+0.2795*L20+ 2.4762*E20+ 0.0303*F20+ 2.0105*G20+ 0.3644*H20- 0.6051*I20 -> 7.1006181 | N20: =-2.2372+0.2795*D20+ 2.4762*E20+ 0.0303*F20+ 2.0105*0.95+ 0.3644*H20- 0.6051*I20 -> 6.7116189 | O20: =C20-N20 -> 0.2393811
A21: Western Europe | B21: Belgium | C21: =6834/(1000) -> 6.834 | D21: =10823/(1000) -> 10.823 | E21: 0.906 | F21: =72199/(1000) -> 72.199 | G21: 0.783 | H21: -0.153 | I21: 0.646 | J21: =-2.2372+0.2795*D21+ 2.4762*E21+ 0.0303*F21+ 2.0105*G21+ 0.3644*H21- 0.6051*I21 -> 6.3464691 | K21: =ABS(C21-J21) -> 0.4875309 | L21: =1.2*D21 -> 12.9876 | M21: =-2.2372+0.2795*L21+ 2.4762*E21+ 0.0303*F21+ 2.0105*G21+ 0.3644*H21- 0.6051*I21 -> 6.9514748 | N21: =-2.2372+0.2795*D21+ 2.4762*E21+ 0.0303*F21+ 2.0105*0.95+ 0.3644*H21- 0.6051*I21 -> 6.6822226 | O21: =C21-N21 -> 0.1517774
A22: Western Europe | B22: France | C22: =6690/(1000) -> 6.69 | D22: =10704/(1000) -> 10.704 | E22: 0.942 | F22: =74000/(1000) -> 74 | G22: 0.822 | H22: -0.147 | I22: 0.571 | J22: =-2.2372+0.2795*D22+ 2.4762*E22+ 0.0303*F22+ 2.0105*G22+ 0.3644*H22- 0.6051*I22 -> 6.5829005 | K22: =ABS(C22-J22) -> 0.1070995 | L22: =1.2*D22 -> 12.8448 | M22: =-2.2372+0.2795*L22+ 2.4762*E22+ 0.0303*F22+ 2.0105*G22+ 0.3644*H22- 0.6051*I22 -> 7.1812541 | N22: =-2.2372+0.2795*D22+ 2.4762*E22+ 0.0303*F22+ 2.0105*0.95+ 0.3644*H22- 0.6051*I22 -> 6.8402445 | O22: =C22-N22 -> -0.1502445
A23: Middle East and North Africa | B23: Bahrain | C23: =6647/(1000) -> 6.647 | D23: =10669/(1000) -> 10.669 | E23: 0.862 | F23: =69495/(1000) -> 69.495 | G23: 0.925 | H23: 0.089 | I23: 0.722 | J23: =-2.2372+0.2795*D23+ 2.4762*E23+ 0.0303*F23+ 2.0105*G23+ 0.3644*H23- 0.6051*I23 -> 6.4402303 | K23: =ABS(C23-J23) -> 0.2067697 | L23: =1.2*D23 -> 12.8028 | M23: =-2.2372+0.2795*L23+ 2.4762*E23+ 0.0303*F23+ 2.0105*G23+ 0.3644*H23- 0.6051*I23 -> 7.0366274 | N23: =-2.2372+0.2795*D23+ 2.4762*E23+ 0.0303*F23+ 2.0105*0.95+ 0.3644*H23- 0.6051*I23 -> 6.4904928 | O23: =C23-N23 -> 0.1565072
A24: Western Europe | B24: Malta | C24: =6602/(1000) -> 6.602 | D24: =10674/(1000) -> 10.674 | E24: 0.931 | F24: =72200/(1000) -> 72.2 | G24: 0.927 | H24: 0.133 | I24: 0.653 | J24: =-2.2372+0.2795*D24+ 2.4762*E24+ 0.0303*F24+ 2.0105*G24+ 0.3644*H24- 0.6051*I24 -> 6.7562536 | K24: =ABS(C24-J24) -> 0.1542536 | L24: =1.2*D24 -> 12.8088 | M24: =-2.2372+0.2795*L24+ 2.4762*E24+ 0.0303*F24+ 2.0105*G24+ 0.3644*H24- 0.6051*I24 -> 7.3529302 | N24: =-2.2372+0.2795*D24+ 2.4762*E24+ 0.0303*F24+ 2.0105*0.95+ 0.3644*H24- 0.6051*I24 -> 6.8024951 | O24: =C24-N24 -> -0.2004951
A25: East Asia | B25: Taiwan Province of China | C25: =6584/(1000) -> 6.584 | D25: =10871/(1000) -> 10.871 | E25: 0.898 | F25: =69600/(1000) -> 69.6 | G25: 0.784 | H25: -0.07 | I25: 0.721 | J25: =-2.2372+0.2795*D25+ 2.4762*E25+ 0.0303*F25+ 2.0105*G25+ 0.3644*H25- 0.6051*I25 -> 6.248199 | K25: =ABS(C25-J25) -> 0.335801 | L25: =1.2*D25 -> 13.0452 | M25: =-2.2372+0.2795*L25+ 2.4762*E25+ 0.0303*F25+ 2.0105*G25+ 0.3644*H25- 0.6051*I25 -> 6.8558879 | N25: =-2.2372+0.2795*D25+ 2.4762*E25+ 0.0303*F25+ 2.0105*0.95+ 0.3644*H25- 0.6051*I25 -> 6.581942 | O25: =C25-N25 -> 0.002058
A26: Middle East and North Africa | B26: United Arab Emirates | C26: =6561/(1000) -> 6.561 | D26: =11085/(1000) -> 11.085 | E26: 0.844 | F26: =67333/(1000) -> 67.333 | G26: 0.932 | H26: 0.074 | I26: 0.589 | J26: =-2.2372+0.2795*D26+ 2.4762*E26+ 0.0303*F26+ 2.0105*G26+ 0.3644*H26- 0.6051*I26 -> 6.5355079 | K26: =ABS(C26-J26) -> 0.0254921 | L26: =1.2*D26 -> 13.302 | M26: =-2.2372+0.2795*L26+ 2.4762*E26+ 0.0303*F26+ 2.0105*G26+ 0.3644*H26- 0.6051*I26 -> 7.1551594 | N26: =-2.2372+0.2795*D26+ 2.4762*E26+ 0.0303*F26+ 2.0105*0.95+ 0.3644*H26- 0.6051*I26 -> 6.5716969 | O26: =C26-N26 -> -0.0106969
A27: Middle East and North Africa | B27: Saudi Arabia | C27: =6494/(1000) -> 6.494 | D27: =10743/(1000) -> 10.743 | E27: 0.891 | F27: =66603/(1000) -> 66.603 | G27: 0.877 | H27: -0.149 | I27: 0.684 | J27: =-2.2372+0.2795*D27+ 2.4762*E27+ 0.0303*F27+ 2.0105*G27+ 0.3644*H27- 0.6051*I27 -> 6.2848581 | K27: =ABS(C27-J27) -> 0.2091419 | L27: =1.2*D27 -> 12.8916 | M27: =-2.2372+0.2795*L27+ 2.4762*E27+ 0.0303*F27+ 2.0105*G27+ 0.3644*H27- 0.6051*I27 -> 6.8853918 | N27: =-2.2372+0.2795*D27+ 2.4762*E27+ 0.0303*F27+ 2.0105*0.95+ 0.3644*H27- 0.6051*I27 -> 6.4316246 | O27: =C27-N27 -> 0.0623754
A28: Western Europe | B28: Spain | C28: =6491/(1000) -> 6.491 | D28: =10571/(1000) -> 10.571 | E28: 0.932 | F28: =74700/(1000) -> 74.7 | G28: 0.761 | H28: -0.081 | I28: 0.745 | J28: =-2.2372+0.2795*D28+ 2.4762*E28+ 0.0303*F28+ 2.0105*G28+ 0.3644*H28- 0.6051*I28 -> 6.3382975 | K28: =ABS(C28-J28) -> 0.1527025 | L28: =1.2*D28 -> 12.6852 | M28: =-2.2372+0.2795*L28+ 2.4762*E28+ 0.0303*F28+ 2.0105*G28+ 0.3644*H28- 0.6051*I28 -> 6.9292164 | N28: =-2.2372+0.2795*D28+ 2.4762*E28+ 0.0303*F28+ 2.0105*0.95+ 0.3644*H28- 0.6051*I28 -> 6.718282 | O28: =C28-N28 -> -0.227282
A29: Western Europe | B29: Italy | C29: =6483/(1000) -> 6.483 | D29: =10623/(1000) -> 10.623 | E29: 0.88 | F29: =73800/(1000) -> 73.8 | G29: 0.693 | H29: -0.084 | I29: 0.866 | J29: =-2.2372+0.2795*D29+ 2.4762*E29+ 0.0303*F29+ 2.0105*G29+ 0.3644*H29- 0.6051*I29 -> 5.9857748 | K29: =ABS(C29-J29) -> 0.4972252 | L29: =1.2*D29 -> 12.7476 | M29: =-2.2372+0.2795*L29+ 2.4762*E29+ 0.0303*F29+ 2.0105*G29+ 0.3644*H29- 0.6051*I29 -> 6.5796005 | N29: =-2.2372+0.2795*D29+ 2.4762*E29+ 0.0303*F29+ 2.0105*0.95+ 0.3644*H29- 0.6051*I29 -> 6.5024733 | O29: =C29-N29 -> -0.0194733
A30: Central and Eastern Europe | B30: Slovenia | C30: =6461/(1000) -> 6.461 | D30: =10529/(1000) -> 10.529 | E30: 0.948 | F30: =71400/(1000) -> 71.4 | G30: 0.949 | H30: -0.101 | I30: 0.806 | J30: =-2.2372+0.2795*D30+ 2.4762*E30+ 0.0303*F30+ 2.0105*G30+ 0.3644*H30- 0.6051*I30 -> 6.5999626 | K30: =ABS(C30-J30) -> 0.1389626 | L30: =1.2*D30 -> 12.6348 | M30: =-2.2372+0.2795*L30+ 2.4762*E30+ 0.0303*F30+ 2.0105*G30+ 0.3644*H30- 0.6051*I30 -> 7.1885337 | N30: =-2.2372+0.2795*D30+ 2.4762*E30+ 0.0303*F30+ 2.0105*0.95+ 0.3644*H30- 0.6051*I30 -> 6.6019731 | O30: =C30-N30 -> -0.1409731
A31: Latin America and Caribbean | B31: Guatemala | C31: =6435/(1000) -> 6.435 | D31: =9053/(1000) -> 9.053 | E31: 0.813 | F31: =64958/(1000) -> 64.958 | G31: 0.906 | H31: -0.038 | I31: 0.775 | J31: =-2.2372+0.2795*D31+ 2.4762*E31+ 0.0303*F31+ 2.0105*G31+ 0.3644*H31- 0.6051*I31 -> 5.6132048 | K31: =ABS(C31-J31) -> 0.8217952 | L31: =1.2*D31 -> 10.8636 | M31: =-2.2372+0.2795*L31+ 2.4762*E31+ 0.0303*F31+ 2.0105*G31+ 0.3644*H31- 0.6051*I31 -> 6.1192675 | N31: =-2.2372+0.2795*D31+ 2.4762*E31+ 0.0303*F31+ 2.0105*0.95+ 0.3644*H31- 0.6051*I31 -> 5.7016668 | O31: =C31-N31 -> 0.7333332
A32: Latin America and Caribbean | B32: Uruguay | C32: =6431/(1000) -> 6.431 | D32: =9966/(1000) -> 9.966 | E32: 0.925 | F32: =69100/(1000) -> 69.1 | G32: 0.896 | H32: -0.092 | I32: 0.59 | J32: =-2.2372+0.2795*D32+ 2.4762*E32+ 0.0303*F32+ 2.0105*G32+ 0.3644*H32- 0.6051*I32 -> 6.3433862 | K32: =ABS(C32-J32) -> 0.0876138 | L32: =1.2*D32 -> 11.9592 | M32: =-2.2372+0.2795*L32+ 2.4762*E32+ 0.0303*F32+ 2.0105*G32+ 0.3644*H32- 0.6051*I32 -> 6.9004856 | N32: =-2.2372+0.2795*D32+ 2.4762*E32+ 0.0303*F32+ 2.0105*0.95+ 0.3644*H32- 0.6051*I32 -> 6.4519532 | O32: =C32-N32 -> -0.0209532
A33: Southeast Asia | B33: Singapore | C33: =6377/(1000) -> 6.377 | D33: =11488/(1000) -> 11.488 | E33: 0.915 | F33: =76953/(1000) -> 76.953 | G33: 0.927 | H33: -0.018 | I33: 0.082 | J33: =-2.2372+0.2795*D33+ 2.4762*E33+ 0.0303*F33+ 2.0105*G33+ 0.3644*H33- 0.6051*I33 -> 7.378651 | K33: =ABS(C33-J33) -> 1.001651 | L33: =1.2*D33 -> 13.7856 | M33: =-2.2372+0.2795*L33+ 2.4762*E33+ 0.0303*F33+ 2.0105*G33+ 0.3644*H33- 0.6051*I33 -> 8.0208302 | N33: =-2.2372+0.2795*D33+ 2.4762*E33+ 0.0303*F33+ 2.0105*0.95+ 0.3644*H33- 0.6051*I33 -> 7.4248925 | O33: =C33-N33 -> -1.0478925
A34: Central and Eastern Europe | B34: Kosovo | C34: =6372/(1000) -> 6.372 | D34: =9318/(1000) -> 9.318 | E34: 0.821 | F34: =63813/(1000) -> 63.813 | G34: 0.869 | H34: 0.257 | I34: 0.917 | J34: =-2.2372+0.2795*D34+ 2.4762*E34+ 0.0303*F34+ 2.0105*G34+ 0.3644*H34- 0.6051*I34 -> 5.6195737 | K34: =ABS(C34-J34) -> 0.7524263 | L34: =1.2*D34 -> 11.1816 | M34: =-2.2372+0.2795*L34+ 2.4762*E34+ 0.0303*F34+ 2.0105*G34+ 0.3644*H34- 0.6051*I34 -> 6.1404499 | N34: =-2.2372+0.2795*D34+ 2.4762*E34+ 0.0303*F34+ 2.0105*0.95+ 0.3644*H34- 0.6051*I34 -> 5.7824242 | O34: =C34-N34 -> 0.5895758
A35: Central and Eastern Europe | B35: Slovakia | C35: =6331/(1000) -> 6.331 | D35: =10369/(1000) -> 10.369 | E35: 0.936 | F35: =69201/(1000) -> 69.201 | G35: 0.766 | H35: -0.124 | I35: 0.911 | J35: =-2.2372+0.2795*D35+ 2.4762*E35+ 0.0303*F35+ 2.0105*G35+ 0.3644*H35- 0.6051*I35 -> 6.0190603 | K35: =ABS(C35-J35) -> 0.3119397 | L35: =1.2*D35 -> 12.4428 | M35: =-2.2372+0.2795*L35+ 2.4762*E35+ 0.0303*F35+ 2.0105*G35+ 0.3644*H35- 0.6051*I35 -> 6.5986874 | N35: =-2.2372+0.2795*D35+ 2.4762*E35+ 0.0303*F35+ 2.0105*0.95+ 0.3644*H35- 0.6051*I35 -> 6.3889923 | O35: =C35-N35 -> -0.0579923
A36: Latin America and Caribbean | B36: Brazil | C36: =6330/(1000) -> 6.33 | D36: =9577/(1000) -> 9.577 | E36: 0.882 | F36: =66601/(1000) -> 66.601 | G36: 0.804 | H36: -0.071 | I36: 0.756 | J36: =-2.2372+0.2795*D36+ 2.4762*E36+ 0.0303*F36+ 2.0105*G36+ 0.3644*H36- 0.6051*I36 -> 5.7747042 | K36: =ABS(C36-J36) -> 0.5552958 | L36: =1.2*D36 -> 11.4924 | M36: =-2.2372+0.2795*L36+ 2.4762*E36+ 0.0303*F36+ 2.0105*G36+ 0.3644*H36- 0.6051*I36 -> 6.3100585 | N36: =-2.2372+0.2795*D36+ 2.4762*E36+ 0.0303*F36+ 2.0105*0.95+ 0.3644*H36- 0.6051*I36 -> 6.0682372 | O36: =C36-N36 -> 0.2617628
A37: Latin America and Caribbean | B37: Mexico | C37: =6317/(1000) -> 6.317 | D37: =9859/(1000) -> 9.859 | E37: 0.831 | F37: =68597/(1000) -> 68.597 | G37: 0.862 | H37: -0.147 | I37: 0.799 | J37: =-2.2372+0.2795*D37+ 2.4762*E37+ 0.0303*F37+ 2.0105*G37+ 0.3644*H37- 0.6051*I37 -> 5.8506111 | K37: =ABS(C37-J37) -> 0.4663889 | L37: =1.2*D37 -> 11.8308 | M37: =-2.2372+0.2795*L37+ 2.4762*E37+ 0.0303*F37+ 2.0105*G37+ 0.3644*H37- 0.6051*I37 -> 6.4017292 | N37: =-2.2372+0.2795*D37+ 2.4762*E37+ 0.0303*F37+ 2.0105*0.95+ 0.3644*H37- 0.6051*I37 -> 6.0275351 | O37: =C37-N37 -> 0.2894649
